Workbook

Sheet Revisions
A1: 1 | B1: Scoring Guide | C1: Review/revise all questions .2 and .3 Scoring guidance - EXCEPT 3.2-3.3 as these have already been revised. This may result in updating the Question field.
A2: 2 | B2: Scoring Guide | C2: Review/revise all questions .2 and .3 Typical Evidence and Evaluation Boundaries - EXCEPT 3.2-3.3 as these have already been revised.
A3: 3 | B3: Scoring Guide | C3: Review/revise all questions .2 and .3 as necessary.
A4: 4 | B4: Review Entry | C4: Re-introduce the .2 and .3 questions.

Sheet Rev Log
A1: No. | B1: Date | C1: Revision
A2: 1 | B2: 46248 | C2: Initial release.

Sheet Overview
A1: Worksheet | B1: Purpose
A2: Instructions | B2: Provides the basic rules for using the QSR workbook, including how to complete the Review Register and Review Entry fields and how scoring, evidence, root cause, and follow-up should be handled.
A3: Review Register | B3: Serves as the master list of review instances and records review-level information such as project, reviewer, review type, status, dates, and review time.
A4: Review Entry | B4: Captures the question-by-question results for each review, including evidence, PM clarification, observations, root cause, quality-system relationship, and follow-up needs.
A5: Scoring Guide | B5: Provides concise 3/2/1 scoring criteria, typical evidence, and question boundaries to help reviewers apply ratings consistently.
A6: Source Matrix | B6: Maps each QSR question to the controlling source documents, sections, pages, and requirements that support the expectation being reviewed.
A7: Actions | B7: Tracks corrective actions, improvement opportunities, ownership, due dates, status, and closure evidence resulting from QSR findings.
A8: KPI Summary | B8: Summarizes QSR performance, review-area results, root-cause trends, evidence-control metrics, completion, and review-effort measures.
A9: Lists | B9: Stores the controlled dropdown values used throughout the workbook, such as review types, statuses, evidence categories, root causes, and action classifications.

Sheet Instructions
A1: Review Register Worksheet
A2: Review Register Column | B2: Purpose
A3: Review ID | B3: Unique identifier for the review instance. Use the established format, such as Project ID 01-R01.
A4: Project ID | B4: Project/job number for the project being reviewed. Project selection criteria: - PM diversity where practical - active projects far enough along to provide meaningful evidence - completed projects preferably within the last 6–12 months - mix of small, medium, and larger projects - mix of routine and 1–2 known-challenged projects per BU - exclusions for projects that are too new, too small, administrative-only, or unusually atypical
A5: Project Description | B5: Short project name or description sufficient to identify the project.
A6: Project Manager | B6: PM responsible for the project being reviewed.
A7: Business Unit | B7: Business Unit that owns or executes the project.
A8: Project Status | B8: Select the project lifecycle status used for the review, currently Active or Completed.
A9: Sold Labor Revenue | B9: Provides a simple measure of project labor size to support comparison of QSR results across projects of different scale. - Labor revenue included in the approved project estimate at the time the project was sold. - Enter the original sold labor revenue from the approved estimate/proposal baseline. Do not update for later changes unless the original commercial baseline itself was formally revised.
A10: Sold Labor Margin % | B10: Establishes the original labor profitability expectation at the time the project was sold for comparison to subsequent performance. - Labor gross margin percentage reflected in the approved estimate at the time the project was sold. - Enter the labor margin percentage from the original approved estimate/proposal baseline. Use the same underlying source as Sold Labor Revenue.
A11: Labor Margin at Review % | B11: Captures the project’s labor margin performance at the time of the review to provide financial-performance context for the QSR results. - The project’s current forecast labor margin at the time of the QSR, or final actual labor margin if the project is complete. - For an active project, use the current forecast/EAC labor margin available at the time of review. For a completed project, use the final actual labor margin.
A12: Labor Margin Variance | B12: Shows the degree of labor margin improvement or erosion relative to the sold labor margin, enabling comparison of financial performance across reviewed projects. - Difference between the project’s labor margin at review and its sold labor margin. - Calculate as: Labor Margin at Review % – Sold Labor Margin %. A negative result indicates margin erosion; a positive result indicates improvement.
A13: Review Sequence | B13: Numeric sequence of reviews for the same project. Use 1 for the initial review, 2 for the first follow-up, etc.
... A20: Notes | B20: Optional review-level context that is useful but does not belong in the individual question results.
A22: Review Entry Worksheet
A23: Review Entry Column | B23: Purpose
A24: Review ID | B24: Identifies the review instance. This links the question result back to the corresponding review in the Review Register.
A25: Review Area | B25: The QSR review area associated with the question, such as Risk Management or Change Management. This is predefined and should not be edited.
A26: Question ID | B26: Unique identifier for the controlled QSR question, such as 4.2. This is predefined and should not be edited.
A27: Controlled Question Text | B27: The approved QSR question being evaluated. This is predefined and should not be edited.
A28: Primary Intent | B28: Brief explanation of what the question is intended to evaluate. Use this to help interpret the question consistently.
A29: Result | B29: Select 3 - Meets Expectation, 2 - Partially Meets Expectation, 1 - Does Not Meet Expectation, N/A - Not Applicable or UTD - Unable To Determine based on the Scoring Guide.
A30: Evidence Status | B30: Select the status that best describes the evidence supporting the result, such as Expected Evidence Found, Acceptable Alternate Evidence, Incomplete Evidence, or Missing Evidence.
A31: Evidence Reviewed / Location | B31: Identify the specific evidence actually reviewed and where it was found or linked so another reviewer could retrace the basis for the rating.
A32: PM Clarification Used? | B32: Select Yes if PM clarification materially helped determine applicability, locate evidence, reconcile records, or understand how the control was performed. Otherwise select No.
A33: PM Clarification Summary | B33: If clarification was used, briefly summarize the information that affected the review conclusion. PM explanation provides context but does not replace required evidence.
A34: Reviewer Observation | B34: For a result of 1 or 2, briefly describe what did not meet the expectation and the material gap observed. For a result of 3, an observation is optional unless useful context should be retained.
... A37: Follow-Up Required? | B37: Select Yes when a Follow-Up Review is needed to verify that the underlying control or expectation has been satisfactorily addressed. A Follow-Up Review is not required solely because an action was created or completed. Follow-Up Reviews are targeted to the specific gap(s) or control(s) requiring verification rather than repeating the full project review.
A39: Scoring Guide Worksheet
A40: Use the Scoring Guide worksheet to help reviewers assign consistent ratings for each QSR question. The Scoring Guide is intended to improve consistency between reviewers. It does not replace reviewer judgment, the controlling source requirements, or the need to consider the project’s lifecycle stage and applicability. N/A and UTD are handled under the separate QSR scoring rules rather than the 3/2/1 question-specific criteria.
A41: The reviewer should filter to the applicable Review Area or Question ID, compare the available evidence to the 3/2/1 criteria, consider the Typical Evidence and Key Boundary, and then enter the selected result on the Review Entry worksheet.
A42: For each question, the worksheet provides:
A43: Scoring Guide Column | B43: Purpose
A44: Review Area | B44: Identifies the QSR review area the question belongs to.
A45: Question ID | B45: Identifies the specific controlled question.
A46: Controlled Question | B46: Shows the approved question being evaluated.
A47: 3 — Meets Expectation | B47: Describes what satisfactory performance looks like when the expectation is substantially fulfilled and supported by evidence.
A48: 2 — Partially Meets Expectation | B48: Describes conditions where meaningful elements are present, but execution, evidence, maintenance, timeliness, approval, or effectiveness is materially incomplete.
A49: 1 — Does Not Meet Expectation | B49: Describes conditions where the applicable expectation is not met, is ineffective, or cannot be reliably verified.
A50: Typical Evidence | B50: Gives examples of records that may support the reviewer’s conclusion. These are examples, not an exhaustive checklist.
...

Sheet Review Register
A1: Review ID | B1: Project ID | C1: Project Description | D1: Project Manager | E1: Business Unit | F1: Project Status | G1: Sold Labor Revenue | H1: Sold Labor Margin % | I1: Labor Margin at Review % | J1: Labor Margin Variance | K1: Review Sequence | L1: Review Type | M1: Reviewer | N1: Review Status | O1: Review Start Date | P1: Review Completion Date | Q1: Review Time (Hours) | R1: Notes
A2: Project ID 01-R01 | B2: Project ID 01 | J2: =IF(OR(H2="",I2=""),"",I2-H2) | K2: 1 | L2: Initial Review | N2: Not Started
A3: Project ID 02-R01 | B3: Project ID 02 | J3: =IF(OR(H3="",I3=""),"",I3-H3) | K3: 1 | L3: Initial Review | N3: Not Started
A4: Project ID 03-R01 | B4: Project ID 03 | J4: =IF(OR(H4="",I4=""),"",I4-H4) | K4: 1 | L4: Initial Review | N4: Not Started
A5: Project ID 04-R01 | B5: Project ID 04 | J5: =IF(OR(H5="",I5=""),"",I5-H5) | K5: 1 | L5: Initial Review | N5: Not Started
A6: Project ID 05-R01 | B6: Project ID 05 | J6: =IF(OR(H6="",I6=""),"",I6-H6) | K6: 1 | L6: Initial Review | N6: Not Started

Sheet Review Entry-Complete
A1: Review ID | B1: Review Area | C1: Question ID | D1: Controlled Question Text | E1: Primary Intent | F1: Evaluation Boundary | G1: Result | H1: Evidence Status | I1: Evidence Reviewed / Location | J1: PM Clarification Used? | K1: PM Clarification Summary | L1: Reviewer Observation | M1: Primary Root Cause | N1: Root-Cause Explanation | O1: Quality-System-Related? | P1: Follow-Up Required? | Q1: Reviewer | R1: Project Manager
A2: Project ID 01-R01 | B2: Project Record Accessibility / Organization | C2: 1.1 | D2: Are project records maintained in the Project Vault or another location permitted by the Project Vault SOP? | E2: Verify that material project records are stored in approved repositories with required traceability. | F2: Scores approved storage location and repository traceability; do not also score general findability or overall record quality unless a separate failure exists. | Q2: =IF('Review Register'!M2="","",'Review Register'!M2) | R2: =IF('Review Register'!D2="","",'Review Register'!D2)
A3: Project ID 01-R01 | B3: Project Record Accessibility / Organization | C3: 1.2 | D3: Are the project’s primary source records readily locatable so the reviewer can understand what was sold, how the project was established for execution, and where supporting QSR evidence is maintained? | E3: Verify that primary source records can be readily located and used to establish the project basis and supporting evidence. | F3: Scores findability and navigation; do not score the substantive quality of each underlying process record here. | Q3: =IF('Review Register'!M2="","",'Review Register'!M2) | R3: =IF('Review Register'!D2="","",'Review Register'!D2)
A4: Project ID 01-R01 | B4: Project Record Accessibility / Organization | C4: 1.3 | D4: Are project records organized, current, controlled, and sufficiently complete to support project execution, traceability, and reliable review? | E4: Verify the overall integrity, currency, control, and completeness of the project record for the lifecycle stage. | F4: Scores overall record integrity; do not duplicate isolated process-artifact failures unless they materially impair the overall project record. | Q4: =IF('Review Register'!M2="","",'Review Register'!M2) | R4: =IF('Review Register'!D2="","",'Review Register'!D2)
A5: Project ID 01-R01 | B5: Sales Handoff / Kickoff | C5: 2.1 | D5: Was Sales Handoff documented and effective in transferring the commercial, scope, schedule, budget, risk, client, and project-background information required by the PM and project team? | E5: Verify effective transfer of the information needed to move the project from sales/estimating into execution. | F5: Scores Sales Handoff; do not duplicate Internal Kickoff, Client Kickoff, or later project-planning controls unless separately deficient. | Q5: =IF('Review Register'!M2="","",'Review Register'!M2) | R5: =IF('Review Register'!D2="","",'Review Register'!D2)
A6: Project ID 01-R01 | B6: Sales Handoff / Kickoff | C6: 2.2 | D6: Was the Internal Kickoff documented and effective in aligning the project team on scope, schedule, budget, responsibilities, quality expectations, risks, and the execution approach? | E6: Verify internal project-team alignment before or at the start of execution. | F6: Scores Internal Kickoff alignment; do not duplicate the Sales Handoff transfer or Client Kickoff alignment unless separately deficient. | Q6: =IF('Review Register'!M2="","",'Review Register'!M2) | R6: =IF('Review Register'!D2="","",'Review Register'!D2)
A7: Project ID 01-R01 | B7: Sales Handoff / Kickoff | C7: 2.3 | D7: Was the Client Kickoff documented and effective in aligning ETG and the client on scope, deliverables, schedule, responsibilities, communications, quality, risks, dependencies, approvals, and success expectations? | E7: Verify alignment between ETG and the client on how the project will be executed and governed. | F7: Scores Client Kickoff alignment; do not duplicate Internal Kickoff or ongoing client communications and project reviews unless separately deficient. | Q7: =IF('Review Register'!M2="","",'Review Register'!M2) | R7: =IF('Review Register'!D2="","",'Review Register'!D2)
A8: Project ID 01-R01 | B8: Project Planning / Workbook Usage | C8: 3.1 | D8: Were all applicable PMLC project-management planning areas considered and appropriately tailored to the project’s size, complexity, risk, contract, and execution needs? | E8: Verify that project-management planning was completed and appropriately tailored to the project. | F8: Scores adequacy and tailoring of planning; do not duplicate Workbook maintenance or specific roles/communications controls unless separately deficient. | Q8: =IF('Review Register'!M2="","",'Review Register'!M2) | R8: =IF('Review Register'!D2="","",'Review Register'!D2)
A9: Project ID 01-R01 | B9: Project Planning / Workbook Usage | C9: 3.2 | D9: Were applicable Project Workbook components populated with sufficient, current, and usable information to support project execution, monitoring, and control? | E9: Verify that applicable Project Workbook components are populated and maintained as usable project-management records. | F9: Scores Workbook content and usability; do not duplicate the broader planning approach or specific risk/change controls unless separately deficient. | Q9: =IF('Review Register'!M2="","",'Review Register'!M2) | R9: =IF('Review Register'!D2="","",'Review Register'!D2)
A10: Project ID 01-R01 | B10: Project Planning / Workbook Usage | C10: 3.3 | D10: Were project roles, responsibilities, deliverables, stakeholder needs, communications, resources, and schedule commitments clearly established and maintained? | E10: Verify that the people, deliverables, communications, resources, and schedule commitments needed for execution are clearly established and maintained. | F10: Scores these execution-planning elements; do not duplicate general Workbook completeness or later review-cadence controls unless separately deficient. | Q10: =IF('Review Register'!M2="","",'Review Register'!M2) | R10: =IF('Review Register'!D2="","",'Review Register'!D2)
A11: Project ID 01-R01 | B11: Risk Management | C11: 4.1 | D11: Were material project risks identified, assessed, and documented at appropriate points beginning with estimating and Sales Handoff? | E11: Verify timely identification, assessment, and documentation of material project risks beginning before execution. | F11: Scores risk identification and assessment; do not duplicate Risk Registry usage or ongoing risk review/mitigation unless separately deficient. | Q11: =IF('Review Register'!M2="","",'Review Register'!M2) | R11: =IF('Review Register'!D2="","",'Review Register'!D2)
A12: Project ID 01-R01 | B12: Risk Management | C12: 4.2 | D12: Was the Project Workbook Risk Registry used and maintained, or was an acceptable equivalent clearly identified and traceable through the Project Workbook or project records? | E12: Verify use of the standard Risk Registry or a clearly identified, traceable acceptable equivalent. | F12: Scores the risk-recording mechanism and traceability; do not duplicate the quality of initial risk identification or ongoing risk management unless separately deficient. | Q12: =IF('Review Register'!M2="","",'Review Register'!M2) | R12: =IF('Review Register'!D2="","",'Review Register'!D2)
A13: Project ID 01-R01 | B13: Risk Management | C13: 4.3 | D13: Were risks reviewed throughout execution, with risk status, impacts, mitigation actions, owners, changes, and dispositions updated as warranted? | E13: Verify active management of identified risks throughout project execution. | F13: Scores ongoing risk review, mitigation, ownership, and disposition; do not duplicate initial risk identification or registry existence unless separately deficient. | Q13: =IF('Review Register'!M2="","",'Review Register'!M2) | R13: =IF('Review Register'!D2="","",'Review Register'!D2)
A14: Project ID 01-R01 | B14: Change Management | C14: 5.1 | D14: Were potential or actual changes to scope, schedule, budget, requirements, design, or other approved project baselines identified and documented when they arose? | E14: Verify that changes to approved project baselines are recognized and documented when they arise. | F14: Scores change identification and documentation; do not duplicate authorization/approval or incorporation of approved changes unless separately deficient. | Q14: =IF('Review Register'!M2="","",'Review Register'!M2) | R14: =IF('Review Register'!D2="","",'Review Register'!D2)
A15: Project ID 01-R01 | B15: Change Management | C15: 5.2 | D15: Were changes evaluated, communicated, authorized, and approved before out-of-scope or at-risk work proceeded, except where the contract expressly permitted another approach? | E15: Verify that changes are evaluated and appropriately authorized before affected work proceeds. | F15: Scores evaluation, communication, authorization, and approval; do not duplicate initial change identification or downstream record updates unless separately deficient. | Q15: =IF('Review Register'!M2="","",'Review Register'!M2) | R15: =IF('Review Register'!D2="","",'Review Register'!D2)
A16: Project ID 01-R01 | B16: Change Management | C16: 5.3 | D16: Were approved changes fully incorporated into applicable project-management, financial, schedule, technical, contractual, and client records? | E16: Verify that approved changes are fully incorporated into the records and baselines they affect. | F16: Scores implementation of approved changes into records; do not duplicate whether the change was identified or approved unless separately deficient. | Q16: =IF('Review Register'!M2="","",'Review Register'!M2) | R16: =IF('Review Register'!D2="","",'Review Register'!D2)
A17: Project ID 01-R01 | B17: Project Monitoring / Review Cadence | C17: 6.1 | D17: Were project reviews conducted at required or appropriate intervals, including applicable project checkpoints and recurring project reviews? | E17: Verify that project reviews and checkpoints occur at required or appropriate intervals. | F17: Scores review occurrence and cadence; do not duplicate the content of reviews or follow-through on resulting actions unless separately deficient. | Q17: =IF('Review Register'!M2="","",'Review Register'!M2) | R17: =IF('Review Register'!D2="","",'Review Register'!D2)
A18: Project ID 01-R01 | B18: Project Monitoring / Review Cadence | C18: 6.2 | D18: Did project reviews address current scope, schedule, budget and forecast, risks, changes, deliverables, quality, resources, client needs, and other material project conditions as applicable? | E18: Verify that project reviews address the material conditions needed to understand and control project performance. | F18: Scores review content and coverage; do not duplicate review cadence or action follow-through unless separately deficient. | Q18: =IF('Review Register'!M2="","",'Review Register'!M2) | R18: =IF('Review Register'!D2="","",'Review Register'!D2)
A19: Project ID 01-R01 | B19: Project Monitoring / Review Cadence | C19: 6.3 | D19: Were decisions, actions, owners, due dates, escalations, and follow-up resulting from project reviews documented and carried through? | E19: Verify that project-review decisions and actions are documented, assigned, escalated where needed, and followed through. | F19: Scores action management resulting from reviews; do not duplicate whether reviews occurred or what topics they covered unless separately deficient. | Q19: =IF('Review Register'!M2="","",'Review Register'!M2) | R19: =IF('Review Register'!D2="","",'Review Register'!D2)
A20: Project ID 01-R01 | B20: Closeout / Lessons Learned | C20: 7.1 | D20: Were applicable technical, administrative, financial, contractual, and client closeout activities completed and documented? | E20: Verify completion and documentation of the applicable overall project closeout activities. | F20: Scores overall closeout completion; do not duplicate specific deliverable/acceptance records or lessons learned unless separately deficient. | Q20: =IF('Review Register'!M2="","",'Review Register'!M2) | R20: =IF('Review Register'!D2="","",'Review Register'!D2)
A21: Project ID 01-R01 | B21: Closeout / Lessons Learned | C21: 7.2 | D21: Were final deliverables, testing and acceptance records, turnover information, approved technical records, client signoffs, and other required closeout records completed and stored appropriately? | E21: Verify completion, approval, turnover, and proper storage of required final project records and deliverables. | F21: Scores final deliverable and acceptance records; do not duplicate broader administrative/financial closeout or lessons learned unless separately deficient. | Q21: =IF('Review Register'!M2="","",'Review Register'!M2) | R21: =IF('Review Register'!D2="","",'Review Register'!D2)
A22: Project ID 01-R01 | B22: Closeout / Lessons Learned | C22: 7.3 | D22: Were lessons learned captured during the project and consolidated at closeout into useful recommendations, with project-specific and quality-system improvement opportunities identified for follow-up where warranted? | E22: Verify that lessons learned are captured and converted into useful project-specific and quality-system improvement opportunities. | F22: Scores lessons learned and improvement capture; do not duplicate general closeout completion or final deliverable records unless separately deficient. | Q22: =IF('Review Register'!M2="","",'Review Register'!M2) | R22: =IF('Review Register'!D2="","",'Review Register'!D2)
A23: Project ID 02-R01 | B23: Project Record Accessibility / Organization | C23: 1.1 | D23: Are project records maintained in the Project Vault or another location permitted by the Project Vault SOP? | E23: Verify that material project records are stored in approved repositories with required traceability. | F23: Scores approved storage location and repository traceability; do not also score general findability or overall record quality unless a separate failure exists. | Q23: =IF('Review Register'!M3="","",'Review Register'!M3) | R23: =IF('Review Register'!D3="","",'Review Register'!D3)
A24: Project ID 02-R01 | B24: Project Record Accessibility / Organization | C24: 1.2 | D24: Are the project’s primary source records readily locatable so the reviewer can understand what was sold, how the project was established for execution, and where supporting QSR evidence is maintained? | E24: Verify that primary source records can be readily located and used to establish the project basis and supporting evidence. | F24: Scores findability and navigation; do not score the substantive quality of each underlying process record here. | Q24: =IF('Review Register'!M3="","",'Review Register'!M3) | R24: =IF('Review Register'!D3="","",'Review Register'!D3)
A25: Project ID 02-R01 | B25: Project Record Accessibility / Organization | C25: 1.3 | D25: Are project records organized, current, controlled, and sufficiently complete to support project execution, traceability, and reliable review? | E25: Verify the overall integrity, currency, control, and completeness of the project record for the lifecycle stage. | F25: Scores overall record integrity; do not duplicate isolated process-artifact failures unless they materially impair the overall project record. | Q25: =IF('Review Register'!M3="","",'Review Register'!M3) | R25: =IF('Review Register'!D3="","",'Review Register'!D3)
A26: Project ID 02-R01 | B26: Sales Handoff / Kickoff | C26: 2.1 | D26: Was Sales Handoff documented and effective in transferring the commercial, scope, schedule, budget, risk, client, and project-background information required by the PM and project team? | E26: Verify effective transfer of the information needed to move the project from sales/estimating into execution. | F26: Scores Sales Handoff; do not duplicate Internal Kickoff, Client Kickoff, or later project-planning controls unless separately deficient. | Q26: =IF('Review Register'!M3="","",'Review Register'!M3) | R26: =IF('Review Register'!D3="","",'Review Register'!D3)
A27: Project ID 02-R01 | B27: Sales Handoff / Kickoff | C27: 2.2 | D27: Was the Internal Kickoff documented and effective in aligning the project team on scope, schedule, budget, responsibilities, quality expectations, risks, and the execution approach? | E27: Verify internal project-team alignment before or at the start of execution. | F27: Scores Internal Kickoff alignment; do not duplicate the Sales Handoff transfer or Client Kickoff alignment unless separately deficient. | Q27: =IF('Review Register'!M3="","",'Review Register'!M3) | R27: =IF('Review Register'!D3="","",'Review Register'!D3)
A28: Project ID 02-R01 | B28: Sales Handoff / Kickoff | C28: 2.3 | D28: Was the Client Kickoff documented and effective in aligning ETG and the client on scope, deliverables, schedule, responsibilities, communications, quality, risks, dependencies, approvals, and success expectations? | E28: Verify alignment between ETG and the client on how the project will be executed and governed. | F28: Scores Client Kickoff alignment; do not duplicate Internal Kickoff or ongoing client communications and project reviews unless separately deficient. | Q28: =IF('Review Register'!M3="","",'Review Register'!M3) | R28: =IF('Review Register'!D3="","",'Review Register'!D3)
A29: Project ID 02-R01 | B29: Project Planning / Workbook Usage | C29: 3.1 | D29: Were all applicable PMLC project-management planning areas considered and appropriately tailored to the project’s size, complexity, risk, contract, and execution needs? | E29: Verify that project-management planning was completed and appropriately tailored to the project. | F29: Scores adequacy and tailoring of planning; do not duplicate Workbook maintenance or specific roles/communications controls unless separately deficient. | Q29: =IF('Review Register'!M3="","",'Review Register'!M3) | R29: =IF('Review Register'!D3="","",'Review Register'!D3)
A30: Project ID 02-R01 | B30: Project Planning / Workbook Usage | C30: 3.2 | D30: Were applicable Project Workbook components populated with sufficient, current, and usable information to support project execution, monitoring, and control? | E30: Verify that applicable Project Workbook components are populated and maintained as usable project-management records. | F30: Scores Workbook content and usability; do not duplicate the broader planning approach or specific risk/change controls unless separately deficient. | Q30: =IF('Review Register'!M3="","",'Review Register'!M3) | R30: =IF('Review Register'!D3="","",'Review Register'!D3)
A31: Project ID 02-R01 | B31: Project Planning / Workbook Usage | C31: 3.3 | D31: Were project roles, responsibilities, deliverables, stakeholder needs, communications, resources, and schedule commitments clearly established and maintained? | E31: Verify that the people, deliverables, communications, resources, and schedule commitments needed for execution are clearly established and maintained. | F31: Scores these execution-planning elements; do not duplicate general Workbook completeness or later review-cadence controls unless separately deficient. | Q31: =IF('Review Register'!M3="","",'Review Register'!M3) | R31: =IF('Review Register'!D3="","",'Review Register'!D3)
A32: Project ID 02-R01 | B32: Risk Management | C32: 4.1 | D32: Were material project risks identified, assessed, and documented at appropriate points beginning with estimating and Sales Handoff? | E32: Verify timely identification, assessment, and documentation of material project risks beginning before execution. | F32: Scores risk identification and assessment; do not duplicate Risk Registry usage or ongoing risk review/mitigation unless separately deficient. | Q32: =IF('Review Register'!M3="","",'Review Register'!M3) | R32: =IF('Review Register'!D3="","",'Review Register'!D3)
A33: Project ID 02-R01 | B33: Risk Management | C33: 4.2 | D33: Was the Project Workbook Risk Registry used and maintained, or was an acceptable equivalent clearly identified and traceable through the Project Workbook or project records? | E33: Verify use of the standard Risk Registry or a clearly identified, traceable acceptable equivalent. | F33: Scores the risk-recording mechanism and traceability; do not duplicate the quality of initial risk identification or ongoing risk management unless separately deficient. | Q33: =IF('Review Register'!M3="","",'Review Register'!M3) | R33: =IF('Review Register'!D3="","",'Review Register'!D3)
A34: Project ID 02-R01 | B34: Risk Management | C34: 4.3 | D34: Were risks reviewed throughout execution, with risk status, impacts, mitigation actions, owners, changes, and dispositions updated as warranted? | E34: Verify active management of identified risks throughout project execution. | F34: Scores ongoing risk review, mitigation, ownership, and disposition; do not duplicate initial risk identification or registry existence unless separately deficient. | Q34: =IF('Review Register'!M3="","",'Review Register'!M3) | R34: =IF('Review Register'!D3="","",'Review Register'!D3)
A35: Project ID 02-R01 | B35: Change Management | C35: 5.1 | D35: Were potential or actual changes to scope, schedule, budget, requirements, design, or other approved project baselines identified and documented when they arose? | E35: Verify that changes to approved project baselines are recognized and documented when they arise. | F35: Scores change identification and documentation; do not duplicate authorization/approval or incorporation of approved changes unless separately deficient. | Q35: =IF('Review Register'!M3="","",'Review Register'!M3) | R35: =IF('Review Register'!D3="","",'Review Register'!D3)
A36: Project ID 02-R01 | B36: Change Management | C36: 5.2 | D36: Were changes evaluated, communicated, authorized, and approved before out-of-scope or at-risk work proceeded, except where the contract expressly permitted another approach? | E36: Verify that changes are evaluated and appropriately authorized before affected work proceeds. | F36: Scores evaluation, communication, authorization, and approval; do not duplicate initial change identification or downstream record updates unless separately deficient. | Q36: =IF('Review Register'!M3="","",'Review Register'!M3) | R36: =IF('Review Register'!D3="","",'Review Register'!D3)
A37: Project ID 02-R01 | B37: Change Management | C37: 5.3 | D37: Were approved changes fully incorporated into applicable project-management, financial, schedule, technical, contractual, and client records? | E37: Verify that approved changes are fully incorporated into the records and baselines they affect. | F37: Scores implementation of approved changes into records; do not duplicate whether the change was identified or approved unless separately deficient. | Q37: =IF('Review Register'!M3="","",'Review Register'!M3) | R37: =IF('Review Register'!D3="","",'Review Register'!D3)
A38: Project ID 02-R01 | B38: Project Monitoring / Review Cadence | C38: 6.1 | D38: Were project reviews conducted at required or appropriate intervals, including applicable project checkpoints and recurring project reviews? | E38: Verify that project reviews and checkpoints occur at required or appropriate intervals. | F38: Scores review occurrence and cadence; do not duplicate the content of reviews or follow-through on resulting actions unless separately deficient. | Q38: =IF('Review Register'!M3="","",'Review Register'!M3) | R38: =IF('Review Register'!D3="","",'Review Register'!D3)
A39: Project ID 02-R01 | B39: Project Monitoring / Review Cadence | C39: 6.2 | D39: Did project reviews address current scope, schedule, budget and forecast, risks, changes, deliverables, quality, resources, client needs, and other material project conditions as applicable? | E39: Verify that project reviews address the material conditions needed to understand and control project performance. | F39: Scores review content and coverage; do not duplicate review cadence or action follow-through unless separately deficient. | Q39: =IF('Review Register'!M3="","",'Review Register'!M3) | R39: =IF('Review Register'!D3="","",'Review Register'!D3)
A40: Project ID 02-R01 | B40: Project Monitoring / Review Cadence | C40: 6.3 | D40: Were decisions, actions, owners, due dates, escalations, and follow-up resulting from project reviews documented and carried through? | E40: Verify that project-review decisions and actions are documented, assigned, escalated where needed, and followed through. | F40: Scores action management resulting from reviews; do not duplicate whether reviews occurred or what topics they covered unless separately deficient. | Q40: =IF('Review Register'!M3="","",'Review Register'!M3) | R40: =IF('Review Register'!D3="","",'Review Register'!D3)
...

Sheet Review Entry
A1: Review ID | B1: Review Area | C1: Question ID | D1: Controlled Question Text | E1: Primary Intent | F1: Result | G1: Evidence Status | H1: Evidence Reviewed / Location | I1: PM Clarification Used? | J1: PM Clarification Summary | K1: Reviewer Observation | L1: Primary Root Cause | M1: Root-Cause Explanation | N1: Follow-Up Required? | O1: Reviewer | P1: Project Manager
A2: Project ID 01-R01 | B2: Project Record Accessibility / Organization | C2: 1.1 | D2: Are project records maintained in the Project Vault or another location permitted by the Project Vault SOP? | E2: Verify that material project records are stored in approved repositories with required traceability. | O2: =IF('Review Register'!M2="","",'Review Register'!M2) | P2: =IF('Review Register'!D2="","",'Review Register'!D2)
A3: Project ID 01-R01 | B3: Project Record Accessibility / Organization | C3: 1.2 | D3: Are the project’s primary source records readily locatable so the reviewer can understand what was sold, how the project was established for execution, and where supporting QSR evidence is maintained? | E3: Verify that primary source records can be readily located and used to establish the project basis and supporting evidence. | O3: =IF('Review Register'!M2="","",'Review Register'!M2) | P3: =IF('Review Register'!D2="","",'Review Register'!D2)
A4: Project ID 01-R01 | B4: Project Record Accessibility / Organization | C4: 1.3 | D4: Are project records organized, current, controlled, and sufficiently complete to support project execution, traceability, and reliable review? | E4: Verify the overall integrity, currency, control, and completeness of the project record for the lifecycle stage. | O4: =IF('Review Register'!M2="","",'Review Register'!M2) | P4: =IF('Review Register'!D2="","",'Review Register'!D2)
A5: Project ID 01-R01 | B5: Sales Handoff / Kickoff | C5: 2.1 | D5: Was Sales Handoff documented and effective in transferring the commercial, scope, schedule, budget, risk, client, and project-background information required by the PM and project team? | E5: Verify effective transfer of the information needed to move the project from sales/estimating into execution. | O5: =IF('Review Register'!M2="","",'Review Register'!M2) | P5: =IF('Review Register'!D2="","",'Review Register'!D2)
A6: Project ID 01-R01 | B6: Sales Handoff / Kickoff | C6: 2.2 | D6: Was the Internal Kickoff documented and effective in aligning the project team on scope, schedule, budget, responsibilities, quality expectations, risks, and the execution approach? | E6: Verify internal project-team alignment before or at the start of execution. | O6: =IF('Review Register'!M2="","",'Review Register'!M2) | P6: =IF('Review Register'!D2="","",'Review Register'!D2)
A7: Project ID 01-R01 | B7: Sales Handoff / Kickoff | C7: 2.3 | D7: Was the Client Kickoff documented and effective in aligning ETG and the client on scope, deliverables, schedule, responsibilities, communications, quality, risks, dependencies, approvals, and success expectations? | E7: Verify alignment between ETG and the client on how the project will be executed and governed. | O7: =IF('Review Register'!M2="","",'Review Register'!M2) | P7: =IF('Review Register'!D2="","",'Review Register'!D2)
A8: Project ID 01-R01 | B8: Project Planning / Workbook Usage | C8: 3.1 | D8: Were all applicable PMLC project-management planning areas considered and appropriately tailored to the project’s size, complexity, risk, contract, and execution needs? | E8: Verify that all applicable PMLC project-management planning areas were considered and appropriately tailored to the project. | O8: =IF('Review Register'!M2="","",'Review Register'!M2) | P8: =IF('Review Register'!D2="","",'Review Register'!D2)
A9: Project ID 01-R01 | B9: Project Planning / Workbook Usage | C9: 3.2 | D9: Were applicable Project Workbook components used and sufficiently populated to provide the required project-management records? | E9: Verify that applicable Project Workbook components supporting the Project Management Plan are used and sufficiently populated to serve as the intended project-management records. | O9: =IF('Review Register'!M2="","",'Review Register'!M2) | P9: =IF('Review Register'!D2="","",'Review Register'!D2)
A10: Project ID 01-R01 | B10: Project Planning / Workbook Usage | C10: 3.3 | D10: Were applicable project roles, responsibilities, deliverables, stakeholder needs, communications, resources, and schedule commitments clearly established and maintained? | E10: Verify that applicable roles and responsibilities, deliverables, stakeholder needs, communications, resources, and schedule commitments are established and maintained to support project execution. | O10: =IF('Review Register'!M2="","",'Review Register'!M2) | P10: =IF('Review Register'!D2="","",'Review Register'!D2)
A11: Project ID 01-R01 | B11: Risk Management | C11: 4.1 | D11: Were material project risks identified, assessed, and documented at appropriate points beginning with estimating and Sales Handoff? | E11: Verify that material project risks are identified and assessed at appropriate stages and that applicable pre-execution risks are carried forward into project planning. | O11: =IF('Review Register'!M2="","",'Review Register'!M2) | P11: =IF('Review Register'!D2="","",'Review Register'!D2)
A12: Project ID 01-R01 | B12: Risk Management | C12: 4.2 | D12: Was the Project Workbook Risk Registry used and maintained, or was an acceptable equivalent clearly identified and traceable through the Project Workbook or project records? | E12: Verify use of the standard Risk Registry or a clearly identified, traceable acceptable equivalent. | O12: =IF('Review Register'!M2="","",'Review Register'!M2) | P12: =IF('Review Register'!D2="","",'Review Register'!D2)
A13: Project ID 01-R01 | B13: Risk Management | C13: 4.3 | D13: Were risks reviewed throughout execution, with risk status, impacts, mitigation actions, owners, changes, and dispositions updated as warranted? | E13: Verify active management of identified risks throughout project execution. | O13: =IF('Review Register'!M2="","",'Review Register'!M2) | P13: =IF('Review Register'!D2="","",'Review Register'!D2)
A14: Project ID 01-R01 | B14: Change Management | C14: 5.1 | D14: Were potential or actual changes to scope, schedule, budget, requirements, design, or other approved project baselines identified and documented when they arose? | E14: Verify that material potential or actual changes to approved project baselines are recognized and documented when they arise. | O14: =IF('Review Register'!M2="","",'Review Register'!M2) | P14: =IF('Review Register'!D2="","",'Review Register'!D2)
A15: Project ID 01-R01 | B15: Change Management | C15: 5.2 | D15: Were changes evaluated, communicated, authorized, and approved before out-of-scope or at-risk work proceeded, except where the contract expressly permitted another approach? | E15: Verify that changes are evaluated and appropriately authorized before affected work proceeds. | O15: =IF('Review Register'!M2="","",'Review Register'!M2) | P15: =IF('Review Register'!D2="","",'Review Register'!D2)
A16: Project ID 01-R01 | B16: Change Management | C16: 5.3 | D16: Were approved changes fully incorporated into applicable project-management, financial, schedule, technical, contractual, and client records? | E16: Verify that approved changes are fully incorporated into the records and baselines they affect. | O16: =IF('Review Register'!M2="","",'Review Register'!M2) | P16: =IF('Review Register'!D2="","",'Review Register'!D2)
A17: Project ID 01-R01 | B17: Project Monitoring / Review Cadence | C17: 6.1 | D17: Were project reviews conducted at required or appropriate intervals, including applicable project checkpoints and recurring project reviews? | E17: Verify that project reviews and checkpoints occur at required or appropriate intervals. | O17: =IF('Review Register'!M2="","",'Review Register'!M2) | P17: =IF('Review Register'!D2="","",'Review Register'!D2)
A18: Project ID 01-R01 | B18: Project Monitoring / Review Cadence | C18: 6.2 | D18: Did project reviews address current scope, schedule, budget and forecast, risks, changes, deliverables, quality, resources, client needs, and other material project conditions as applicable? | E18: Verify that project reviews address the material conditions needed to understand and control project performance. | O18: =IF('Review Register'!M2="","",'Review Register'!M2) | P18: =IF('Review Register'!D2="","",'Review Register'!D2)
A19: Project ID 01-R01 | B19: Project Monitoring / Review Cadence | C19: 6.3 | D19: Were decisions, actions, owners, due dates, escalations, and follow-up resulting from project reviews documented and carried through? | E19: Verify that project-review decisions and actions are documented, assigned, escalated where needed, and followed through. | O19: =IF('Review Register'!M2="","",'Review Register'!M2) | P19: =IF('Review Register'!D2="","",'Review Register'!D2)
A20: Project ID 01-R01 | B20: Closeout / Lessons Learned | C20: 7.1 | D20: Were applicable technical, administrative, financial, contractual, and client closeout activities completed and documented? | E20: Verify completion and documentation of the applicable overall project closeout activities. | O20: =IF('Review Register'!M2="","",'Review Register'!M2) | P20: =IF('Review Register'!D2="","",'Review Register'!D2)
A21: Project ID 01-R01 | B21: Closeout / Lessons Learned | C21: 7.2 | D21: Were final deliverables, testing and acceptance records, turnover information, approved technical records, client signoffs, and other required closeout records completed and stored appropriately? | E21: Verify completion, approval, turnover, and proper storage of required final project records and deliverables. | O21: =IF('Review Register'!M2="","",'Review Register'!M2) | P21: =IF('Review Register'!D2="","",'Review Register'!D2)
A22: Project ID 01-R01 | B22: Closeout / Lessons Learned | C22: 7.3 | D22: Were lessons learned captured during the project and consolidated at closeout into useful recommendations, with project-specific and quality-system improvement opportunities identified for follow-up where warranted? | E22: Verify that lessons learned are captured and converted into useful project-specific and quality-system improvement opportunities. | O22: =IF('Review Register'!M2="","",'Review Register'!M2) | P22: =IF('Review Register'!D2="","",'Review Register'!D2)
A23: Project ID 02-R01 | B23: Project Record Accessibility / Organization | C23: 1.1 | D23: Are project records maintained in the Project Vault or another location permitted by the Project Vault SOP? | E23: Verify that material project records are stored in approved repositories with required traceability. | O23: =IF('Review Register'!M3="","",'Review Register'!M3) | P23: =IF('Review Register'!D3="","",'Review Register'!D3)
A24: Project ID 02-R01 | B24: Project Record Accessibility / Organization | C24: 1.2 | D24: Are the project’s primary source records readily locatable so the reviewer can understand what was sold, how the project was established for execution, and where supporting QSR evidence is maintained? | E24: Verify that primary source records can be readily located and used to establish the project basis and supporting evidence. | O24: =IF('Review Register'!M3="","",'Review Register'!M3) | P24: =IF('Review Register'!D3="","",'Review Register'!D3)
A25: Project ID 02-R01 | B25: Project Record Accessibility / Organization | C25: 1.3 | D25: Are project records organized, current, controlled, and sufficiently complete to support project execution, traceability, and reliable review? | E25: Verify the overall integrity, currency, control, and completeness of the project record for the lifecycle stage. | O25: =IF('Review Register'!M3="","",'Review Register'!M3) | P25: =IF('Review Register'!D3="","",'Review Register'!D3)
A26: Project ID 02-R01 | B26: Sales Handoff / Kickoff | C26: 2.1 | D26: Was Sales Handoff documented and effective in transferring the commercial, scope, schedule, budget, risk, client, and project-background information required by the PM and project team? | E26: Verify effective transfer of the information needed to move the project from sales/estimating into execution. | O26: =IF('Review Register'!M3="","",'Review Register'!M3) | P26: =IF('Review Register'!D3="","",'Review Register'!D3)
A27: Project ID 02-R01 | B27: Sales Handoff / Kickoff | C27: 2.2 | D27: Was the Internal Kickoff documented and effective in aligning the project team on scope, schedule, budget, responsibilities, quality expectations, risks, and the execution approach? | E27: Verify internal project-team alignment before or at the start of execution. | O27: =IF('Review Register'!M3="","",'Review Register'!M3) | P27: =IF('Review Register'!D3="","",'Review Register'!D3)
A28: Project ID 02-R01 | B28: Sales Handoff / Kickoff | C28: 2.3 | D28: Was the Client Kickoff documented and effective in aligning ETG and the client on scope, deliverables, schedule, responsibilities, communications, quality, risks, dependencies, approvals, and success expectations? | E28: Verify alignment between ETG and the client on how the project will be executed and governed. | O28: =IF('Review Register'!M3="","",'Review Register'!M3) | P28: =IF('Review Register'!D3="","",'Review Register'!D3)
A29: Project ID 02-R01 | B29: Project Planning / Workbook Usage | C29: 3.1 | D29: Were all applicable PMLC project-management planning areas considered and appropriately tailored to the project’s size, complexity, risk, contract, and execution needs? | E29: Verify that all applicable PMLC project-management planning areas were considered and appropriately tailored to the project. | O29: =IF('Review Register'!M3="","",'Review Register'!M3) | P29: =IF('Review Register'!D3="","",'Review Register'!D3)
A30: Project ID 02-R01 | B30: Project Planning / Workbook Usage | C30: 3.2 | D30: Were applicable Project Workbook components used and sufficiently populated to provide the required project-management records? | E30: Verify that applicable Project Workbook components supporting the Project Management Plan are used and sufficiently populated to serve as the intended project-management records. | O30: =IF('Review Register'!M3="","",'Review Register'!M3) | P30: =IF('Review Register'!D3="","",'Review Register'!D3)
A31: Project ID 02-R01 | B31: Project Planning / Workbook Usage | C31: 3.3 | D31: Were applicable project roles, responsibilities, deliverables, stakeholder needs, communications, resources, and schedule commitments clearly established and maintained? | E31: Verify that applicable roles and responsibilities, deliverables, stakeholder needs, communications, resources, and schedule commitments are established and maintained to support project execution. | O31: =IF('Review Register'!M3="","",'Review Register'!M3) | P31: =IF('Review Register'!D3="","",'Review Register'!D3)
A32: Project ID 02-R01 | B32: Risk Management | C32: 4.1 | D32: Were material project risks identified, assessed, and documented at appropriate points beginning with estimating and Sales Handoff? | E32: Verify that material project risks are identified and assessed at appropriate stages and that applicable pre-execution risks are carried forward into project planning. | O32: =IF('Review Register'!M3="","",'Review Register'!M3) | P32: =IF('Review Register'!D3="","",'Review Register'!D3)
A33: Project ID 02-R01 | B33: Risk Management | C33: 4.2 | D33: Was the Project Workbook Risk Registry used and maintained, or was an acceptable equivalent clearly identified and traceable through the Project Workbook or project records? | E33: Verify use of the standard Risk Registry or a clearly identified, traceable acceptable equivalent. | O33: =IF('Review Register'!M3="","",'Review Register'!M3) | P33: =IF('Review Register'!D3="","",'Review Register'!D3)
A34: Project ID 02-R01 | B34: Risk Management | C34: 4.3 | D34: Were risks reviewed throughout execution, with risk status, impacts, mitigation actions, owners, changes, and dispositions updated as warranted? | E34: Verify active management of identified risks throughout project execution. | O34: =IF('Review Register'!M3="","",'Review Register'!M3) | P34: =IF('Review Register'!D3="","",'Review Register'!D3)
A35: Project ID 02-R01 | B35: Change Management | C35: 5.1 | D35: Were potential or actual changes to scope, schedule, budget, requirements, design, or other approved project baselines identified and documented when they arose? | E35: Verify that material potential or actual changes to approved project baselines are recognized and documented when they arise. | O35: =IF('Review Register'!M3="","",'Review Register'!M3) | P35: =IF('Review Register'!D3="","",'Review Register'!D3)
A36: Project ID 02-R01 | B36: Change Management | C36: 5.2 | D36: Were changes evaluated, communicated, authorized, and approved before out-of-scope or at-risk work proceeded, except where the contract expressly permitted another approach? | E36: Verify that changes are evaluated and appropriately authorized before affected work proceeds. | O36: =IF('Review Register'!M3="","",'Review Register'!M3) | P36: =IF('Review Register'!D3="","",'Review Register'!D3)
A37: Project ID 02-R01 | B37: Change Management | C37: 5.3 | D37: Were approved changes fully incorporated into applicable project-management, financial, schedule, technical, contractual, and client records? | E37: Verify that approved changes are fully incorporated into the records and baselines they affect. | O37: =IF('Review Register'!M3="","",'Review Register'!M3) | P37: =IF('Review Register'!D3="","",'Review Register'!D3)
A38: Project ID 02-R01 | B38: Project Monitoring / Review Cadence | C38: 6.1 | D38: Were project reviews conducted at required or appropriate intervals, including applicable project checkpoints and recurring project reviews? | E38: Verify that project reviews and checkpoints occur at required or appropriate intervals. | O38: =IF('Review Register'!M3="","",'Review Register'!M3) | P38: =IF('Review Register'!D3="","",'Review Register'!D3)
A39: Project ID 02-R01 | B39: Project Monitoring / Review Cadence | C39: 6.2 | D39: Did project reviews address current scope, schedule, budget and forecast, risks, changes, deliverables, quality, resources, client needs, and other material project conditions as applicable? | E39: Verify that project reviews address the material conditions needed to understand and control project performance. | O39: =IF('Review Register'!M3="","",'Review Register'!M3) | P39: =IF('Review Register'!D3="","",'Review Register'!D3)
A40: Project ID 02-R01 | B40: Project Monitoring / Review Cadence | C40: 6.3 | D40: Were decisions, actions, owners, due dates, escalations, and follow-up resulting from project reviews documented and carried through? | E40: Verify that project-review decisions and actions are documented, assigned, escalated where needed, and followed through. | O40: =IF('Review Register'!M3="","",'Review Register'!M3) | P40: =IF('Review Register'!D3="","",'Review Register'!D3)
...

Sheet Scoring Guide
A1: Review Area | B1: Question ID | C1: Controlled Question | D1: 3 — Meets Expectation | E1: 2 — Partially Meets Expectation | F1: 1 — Does Not Meet Expectation | G1: Typical Evidence | H1: Evaluation Boundary
A2: Project Record Accessibility / Organization | B2: 1.1 | C2: Are project records maintained in the Project Vault or another location permitted by the Project Vault SOP? | D2: Material records are in Project Vault or permitted alternate locations with required traceability. | E2: Most records comply, but some material records or required links are inconsistently maintained. | F2: Material records are outside approved locations or cannot be traced to an approved repository. | G2: Project Vault project folder and applicable standard subfolders; records applicable to the project; links to approved alternate storage locations, including large files, virtual machines, or client-hosted deliverables. | H2: Evaluates whether records applicable to the project are maintained in an approved repository. Applicability depends on the project’s scope, execution approach, and activities performed. The existence of a standard Project Vault folder or template does not, by itself, mean the corresponding record is required. Does not evaluate general file organization or the substantive adequacy of individual records.
A3: Project Record Accessibility / Organization | B3: 1.2 | C3: Are the project’s primary source records readily locatable so the reviewer can understand what was sold, how the project was established for execution, and where supporting QSR evidence is maintained? | D3: Primary source records are readily found without material searching or PM assistance. | E3: Records are ultimately found, but some require PM assistance or are stored unexpectedly. | F3: Material source records cannot be reliably located or verified after clarification. | G3: Contract/authorization; proposal; estimate/WBS; Workbook; Notebook; schedule; approved links. | H3: Scores findability—not the quality of each underlying process record.
A4: Project Record Accessibility / Organization | B4: 1.3 | C4: Are project records organized, current, controlled, and sufficiently complete to support project execution, traceability, and reliable review? | D4: Records are substantially current, controlled, and complete for the project stage. | E4: Records are usable but contain material gaps, outdated information, unclear versions, or incomplete approvals. | F4: Records are materially disorganized, outdated, uncontrolled, or incomplete. | G4: Representative files; current logs/registers; approvals; revisions; links; final records. | H4: Scores overall record integrity—not isolated process-artifact failures.
A5: Sales Handoff / Kickoff | B5: 2.1 | C5: Was Sales Handoff documented and effective in transferring the commercial, scope, schedule, budget, risk, client, and project-background information required by the PM and project team? | D5: Handoff is documented and materially transfers the information needed for successful technical and commercial execution. | E5: Handoff occurred and transferred meaningful information, but material elements, documentation, or communication are incomplete. | F5: Handoff is absent, cannot be reliably evidenced, or fails to transfer material information needed for execution. | G5: Sales Handover agenda and meeting minutes documenting discussion or transfer of applicable project information, including scope and deliverables, schedule, budget/WBS, risks and opportunities, client expectations/contacts, contractual or commercial considerations, and relevant project background; referenced or attached supporting records where identified in the handoff documentation; PM clarification where the documented handoff is unclear. | H5: Evaluates whether applicable information was actually transferred from Sales to Operations, based primarily on the documented Sales Handover and targeted PM clarification where needed. The existence of underlying sales or project records alone does not demonstrate that the information was communicated during the handoff.
A6: Sales Handoff / Kickoff | B6: 2.2 | C6: Was the Internal Kickoff documented and effective in aligning the project team on scope, schedule, budget, responsibilities, quality expectations, risks, and the execution approach? | D6: Internal Kickoff is documented and materially aligns the project team on the required execution topics. | E6: Kickoff occurred and provides meaningful alignment, but material topics, participants, minutes, or follow-up are incomplete. | F6: Kickoff is absent, cannot be reliably evidenced, or does not materially align the project team on execution expectations. | G6: Internal Kickoff agenda/minutes; RACI; proposal; schedule; WBS/budget; Risk Registry; quality-role assignments. | H6: Scores internal team alignment; do not duplicate Sales Handoff or Client Kickoff unless separately deficient.
